<?xml version="1.0"?>

<robot 
    name="boris" 
    xmlns:xacro="http://ros.org/wiki/xacro">

<!-- ###################### -->
<!-- ###      Root      ### -->
<!-- ###################### -->

  <link name="root_link" />

<!-- ###################### -->
<!-- ###      Base      ### -->
<!-- ###################### -->

  <link name="base_link">
    <inertial>
      <origin xyz="0 0 0" rpy="0 0 0" />
      <mass value="1"/>
      <inertia
        ixx="1.0" ixy="0.0" ixz="0.0"
        iyy="1.0" iyz="0.0"
        izz="1.0"/>
    </inertial>

    <visual>
      <origin xyz="0 0 0" rpy="0 0 0" />
      <geometry>
        <mesh filename="package://boris_description/meshes/base_link.STL" />
      </geometry>
      <material name="white"/>
    </visual>

    <collision>
      <origin xyz="0 0 0" rpy="0 0 0" />
      <geometry>
        <mesh filename="package://boris_description/meshes/base_link.STL" />
      </geometry>
    </collision>
  </link>

  <joint name="base_joint" type="fixed">
    <origin xyz="0 0 0"
            rpy="0 0 0" />
    <parent link="root_link" />
    <child  link="base_link" />
  </joint>

<!-- ###################### -->
<!-- ### Base Rotation #### -->
<!-- ###################### -->

  <link name="base_rotation_link">
    <inertial>
      <origin xyz="0 0 0" rpy="0 0 0" />
      <mass value="1"/>
      <inertia
        ixx="1.0" ixy="0.0" ixz="0.0"
        iyy="1.0" iyz="0.0"
        izz="1.0"/>
    </inertial>

    <visual>
      <origin xyz="0 0 0" rpy="0 0 0" />
      <geometry>
        <mesh filename="package://boris_description/meshes/base_rotation_link.STL" />
      </geometry>
      <material name="white"/>
    </visual>

    <collision>
      <origin xyz="0 0 0" rpy="0 0 0" />
      <geometry>
        <mesh filename="package://boris_description/meshes/base_rotation_link.STL" />
      </geometry>
    </collision>
  </link>

  <joint name="base_rotation_joint" type="revolute">
    <origin xyz="0 0 0"
            rpy="0 0 0" />
    <parent link="base_link" />
    <child  link="base_rotation_link" />
    <axis xyz="0 0 1" />
    <limit lower="-1.40" upper="1.40" effort="30.0" velocity="0.7" />
    <dynamics damping="1.0" />
  </joint>

<!-- ###################### -->
<!-- ###   Upper Arm   #### -->
<!-- ###################### -->

  <link name="upper_arm_link">
    <inertial>
      <origin xyz="0 0 0" rpy="0 0 0" />
      <mass value="1"/>
      <inertia
        ixx="1.0" ixy="0.0" ixz="0.0"
        iyy="1.0" iyz="0.0"
        izz="1.0"/>
    </inertial>

    <visual>
      <origin xyz="0 0 0" rpy="0 0 0" />
      <geometry>
        <mesh filename="package://boris_description/meshes/upper_arm_link.STL" />
      </geometry>
      <material name="white"/>
    </visual>

    <collision>
      <origin xyz="0 0 0" rpy="0 0 0" />
      <geometry>
        <mesh filename="package://boris_description/meshes/upper_arm_link.STL" />
      </geometry>
    </collision>
  </link>

  <joint name="upper_arm_joint" type="revolute">
    <origin xyz="-0.0290000000000001 0 0.062"
            rpy="0 0 0" />
    <parent link="base_rotation_link" />
    <child  link="upper_arm_link" />
    <axis xyz="0 1 0" />
    <limit lower="-0.45" upper="1.40" effort="30.0" velocity="0.7" />
    <dynamics damping="1.0" />
  </joint>

<!-- ###################### -->
<!-- ### Upper Support #### -->
<!-- ###################### -->

  <link name="upper_support_link">
    <inertial>
      <origin xyz="0 0 0" rpy="0 0 0" />
      <mass value="1"/>
      <inertia
        ixx="1.0" ixy="0.0" ixz="0.0"
        iyy="1.0" iyz="0.0"
        izz="1.0"/>
    </inertial>

    <visual>
      <origin xyz="0 0 0" rpy="0 0 0" />
      <geometry>
        <mesh filename="package://boris_description/meshes/upper_support_link.STL" />
      </geometry>
      <material name="white"/>
    </visual>

    <collision>
      <origin xyz="0 0 0" rpy="0 0 0" />
      <geometry>
        <mesh filename="package://boris_description/meshes/upper_support_link.STL" />
      </geometry>
    </collision>
  </link>

  <joint name="upper_support_joint" type="revolute">
    <origin xyz="0.035 0 0.032" rpy="0 0 0" />
    <parent link="base_rotation_link" />
    <child  link="upper_support_link" />
    <axis xyz="0 1 0" />
    <limit lower="-0.45" upper="1.40" effort="30.0" velocity="0.7" />
    <dynamics damping="1.0" />
    <mimic joint="upper_arm_joint" multiplier="1" offset="0" />
  </joint>

<!-- ###################### -->
<!-- ## Elbow Connection ## -->
<!-- ###################### -->

  <link name="elbow_connection_link">
    <inertial>
      <origin xyz="0 0 0" rpy="0 0 0" />
      <mass value="1"/>
      <inertia
        ixx="1.0" ixy="0.0" ixz="0.0"
        iyy="1.0" iyz="0.0"
        izz="1.0"/>
    </inertial>

    <visual>
      <origin xyz="0 0 0" rpy="0 0 0" />
      <geometry>
        <mesh filename="package://boris_description/meshes/elbow_connection_link.STL" />
      </geometry>
      <material name="white"/>
    </visual>

    <collision>
      <origin xyz="0 0 0" rpy="0 0 0" />
      <geometry>
        <mesh filename="package://boris_description/meshes/elbow_connection_link.STL" />
      </geometry>
    </collision>
  </link>

  <joint name="elbow_connection_joint" type="revolute">
    <origin xyz="0 0 0.17"
            rpy="0 0 0" />
    <parent link="upper_arm_link" />
    <child  link="elbow_connection_link" />
    <axis xyz="0 -1 0" />
    <limit lower="-0.45" upper="1.40" effort="30.0" velocity="0.7" />
    <dynamics damping="1.0" />
    <mimic joint="upper_arm_joint" multiplier="1" offset="0" />
  </joint>

<!-- ###################### -->
<!-- ###   Lower Arm   #### -->
<!-- ###################### -->

  <link name="lower_arm_link">
    <inertial>
      <origin xyz="0 0 0" rpy="0 0 0" />
      <mass value="1"/>
      <inertia
        ixx="1.0" ixy="0.0" ixz="0.0"
        iyy="1.0" iyz="0.0"
        izz="1.0"/>
    </inertial>

    <visual>
      <origin xyz="0 0 0" rpy="0 0 0" />
      <geometry>
        <mesh filename="package://boris_description/meshes/lower_arm_link.STL" />
      </geometry>
      <material name="white"/>
    </visual>

    <collision>
      <origin xyz="0 0 0" rpy="0 0 0" />
      <geometry>
        <mesh filename="package://boris_description/meshes/lower_arm_link.STL" />
      </geometry>
    </collision>
  </link>

  <joint name="lower_arm_joint" type="revolute">
    <origin xyz="0.0639999585758989 0 -0.030000000000005"
            rpy="0 0 0" />
    <parent link="elbow_connection_link" />
    <child  link="lower_arm_link" />
    <axis xyz="0 1 0" />
    <limit lower="-0.50" upper="1.20" effort="30.0" velocity="0.7" />
    <dynamics damping="1.0" />
  </joint>

<!-- ###################### -->
<!-- ### Lower Support #### -->
<!-- ###################### -->

  <link name="lower_support_link">
    <inertial>
      <origin xyz="0 0 0" rpy="0 0 0" />
      <mass value="1"/>
      <inertia
        ixx="1.0" ixy="0.0" ixz="0.0"
        iyy="1.0" iyz="0.0"
        izz="1.0"/>
    </inertial>

    <visual>
      <origin xyz="0 0 0" rpy="0 0 0" />
      <geometry>
        <mesh filename="package://boris_description/meshes/lower_support_link.STL" />
      </geometry>
      <material name="white"/>
    </visual>

    <collision>
      <origin xyz="0 0 0" rpy="0 0 0" />
      <geometry>
        <mesh filename="package://boris_description/meshes/lower_support_link.STL" />
      </geometry>
    </collision>
  </link>

  <joint name="lower_support_joint" type="revolute">
    <origin xyz="0.0939980350675133 0 0.0339790858858603"
            rpy="0 0 0" />
    <parent link="elbow_connection_link" />
    <child  link="lower_support_link" />
    <axis xyz="0 1 0" />
    <limit lower="-0.50" upper="1.20" effort="30.0" velocity="0.7" />
    <dynamics damping="1.0" />
    <mimic joint="lower_arm_joint" multiplier="1" offset="0" />
  </joint>

<!-- ###################### -->
<!-- ## Wrist Connection ## -->
<!-- ###################### -->

  <link name="wrist_connection_link">
    <inertial>
      <origin xyz="0 0 0" rpy="0 0 0" />
      <mass value="1"/>
      <inertia
        ixx="1.0" ixy="0.0" ixz="0.0"
        iyy="1.0" iyz="0.0"
        izz="1.0"/>
    </inertial>

    <visual>
      <origin xyz="0 0 0" rpy="0 0 0" />
      <geometry>
        <mesh filename="package://boris_description/meshes/wrist_connection_link.STL" />
      </geometry>
      <material name="white"/>
    </visual>

    <collision>
      <origin xyz="0 0 0" rpy="0 0 0" />
      <geometry>
        <mesh filename="package://boris_description/meshes/wrist_connection_link.STL" />
      </geometry>
    </collision>
  </link>

  <joint name="wrist_connection_joint" type="revolute">
    <origin xyz="0.17 0 0" rpy="0 0 0" />
    <parent link="lower_arm_link" />
    <child  link="wrist_connection_link" />
    <axis xyz="0 -1 0" />
    <limit lower="-0.50" upper="1.20" effort="30.0" velocity="0.7" />
    <dynamics damping="1.0" />
    <mimic joint="lower_arm_joint" multiplier="1" offset="0" />
  </joint>

<!-- ###################### -->
<!-- ####    Wrist     #### -->
<!-- ###################### -->

  <link name="wrist_link">
    <inertial>
      <origin xyz="0 0 0" rpy="0 0 0" />
      <mass value="1"/>
      <inertia
        ixx="1.0" ixy="0.0" ixz="0.0"
        iyy="1.0" iyz="0.0"
        izz="1.0"/>
    </inertial>

    <visual>
      <origin xyz="0 0 0" rpy="0 0 0" />
      <geometry>
        <mesh filename="package://boris_description/meshes/wrist_link.STL" />
      </geometry>
      <material
        name="">
        <color
          rgba="1 1 1 1" />
      </material>
    </visual>

    <collision>
      <origin xyz="0 0 0" rpy="0 0 0" />
      <geometry>
        <mesh filename="package://boris_description/meshes/wrist_link.STL" />
      </geometry>
    </collision>
  </link>

  <joint name="wrist_joint" type="revolute">
    <origin xyz="0.0614993382896367 0 0.0220018496935334"
            rpy="0 0 0" />
    <parent link="wrist_connection_link" />
    <child  link="wrist_link" />
    <axis xyz="-1 0 0" />
    <limit lower="-1.40" upper="1.40" effort="30.0" velocity="0.7" />
    <dynamics damping="1.0" />
  </joint>

<!-- ###################### -->
<!-- ####     Hand     #### -->
<!-- ###################### -->

  <link name="hand_link">
    <inertial>
      <origin xyz="0 0 0" rpy="0 0 0" />
      <mass value="1"/>
      <inertia
        ixx="1.0" ixy="0.0" ixz="0.0"
        iyy="1.0" iyz="0.0"
        izz="1.0"/>
    </inertial>

    <visual>
      <origin xyz="0 0 0" rpy="0 0 0" />
      <geometry>
        <mesh filename="package://boris_description/meshes/hand_link.STL" />
      </geometry>
      <material name="white"/>
    </visual>

    <collision>
      <origin xyz="0 0 0" rpy="0 0 0" />
      <geometry>
        <mesh filename="package://boris_description/meshes/hand_link.STL" />
      </geometry>
    </collision>
  </link>

  <joint name="hand_joint" type="revolute">
    <origin xyz="0.0339425075717842 0 -0.00785697913242348"
            rpy="0 0 0" />
    <parent link="wrist_link" />
    <child  link="hand_link" />
    <axis xyz="0 1 0" />
    <limit lower="-1.40" upper="1.40" effort="30.0" velocity="0.7" />
    <dynamics damping="1.0" />
  </joint>

<!-- ###################### -->
<!-- ####   Gripper    #### -->
<!-- ###################### -->

  <link name="gripper_right_link">
    <inertial>
      <origin xyz="0 0 0" rpy="0 0 0" />
      <mass value="1"/>
      <inertia
        ixx="1.0" ixy="0.0" ixz="0.0"
        iyy="1.0" iyz="0.0"
        izz="1.0"/>
    </inertial>

    <visual>
      <origin xyz="0 0 0" rpy="0 0 0" />
      <geometry>
        <mesh filename="package://boris_description/meshes/gripper_right_link.STL" />
      </geometry>
      <material name="white"/>
    </visual>

    <collision>
      <origin xyz="0 0 0" rpy="0 0 0" />
      <geometry>
        <mesh filename="package://boris_description/meshes/gripper_right_link.STL" />
      </geometry>
    </collision>
  </link>

  <joint name="gripper_right_joint" type="revolute">
    <origin xyz="0.0534999999999999 -0.0195671204842695 0.003"
            rpy="0 0 0" />
    <parent link="hand_link" />
    <child  link="gripper_right_link" />
    <axis xyz="0 0 1" />
    <limit lower="-1.00" upper="0.00" effort="30.0" velocity="0.7" />
    <dynamics damping="1.0" />
  </joint>

<!-- ###################### -->
<!-- ### Gripper Mimic #### -->
<!-- ###################### -->

  <link name="gripper_right_front_link">
    <inertial>
      <origin xyz="0 0 0" rpy="0 0 0" />
      <mass value="1"/>
      <inertia
        ixx="1.0" ixy="0.0" ixz="0.0"
        iyy="1.0" iyz="0.0"
        izz="1.0"/>
    </inertial>

    <visual>
      <origin xyz="0 0 0" rpy="0 0 0" />
      <geometry>
        <mesh filename="package://boris_description/meshes/gripper_right_front_link.STL" />
      </geometry>
      <material name="white"/>
    </visual>

    <collision>
      <origin xyz="0 0 0" rpy="0 0 0" />
      <geometry>
        <mesh filename="package://boris_description/meshes/gripper_right_front_link.STL" />
      </geometry>
    </collision>
  </link>

  <joint name="gripper_right_front_joint" type="revolute">
    <origin xyz="0.0299999249139151 6.71204842689031E-05 0.00025"
            rpy="0 0 0" />
    <parent link="gripper_right_link" />
    <child  link="gripper_right_front_link" />
    <axis xyz="0 0 -1" />
    <limit lower="-1.00" upper="0.00" effort="30.0" velocity="0.7" />
    <dynamics damping="1.0" />
    <mimic joint="gripper_right_joint" multiplier="1" offset="0" />
  </joint>

<!-- ###################### -->
<!-- ### Gripper Mimic #### -->
<!-- ###################### -->

  <link name="gripper_left_link">
    <inertial>
      <origin xyz="0 0 0" rpy="0 0 0" />
      <mass value="1"/>
      <inertia
        ixx="1.0" ixy="0.0" ixz="0.0"
        iyy="1.0" iyz="0.0"
        izz="1.0"/>
    </inertial>

    <visual>
      <origin xyz="0 0 0" rpy="0 0 0" />
      <geometry>
        <mesh filename="package://boris_description/meshes/gripper_left_link.STL" />
      </geometry>
      <material name="white"/>
    </visual>

    <collision>
      <origin xyz="0 0 0" rpy="0 0 0" />
      <geometry>
        <mesh filename="package://boris_description/meshes/gripper_left_link.STL" />
      </geometry>
    </collision>
  </link>

  <joint name="gripper_left_joint" type="revolute">
    <origin xyz="0.0535 0.0194328795157305 0.00299999999999997"
            rpy="0 0 0" />
    <parent link="hand_link" />
    <child  link="gripper_left_link" />
    <axis xyz="0 0 -1" />
    <limit lower="-1.00" upper="0.00" effort="30.0" velocity="0.7" />
    <dynamics damping="1.0" />
    <mimic joint="gripper_right_joint" multiplier="1" offset="0" />
  </joint>

<!-- ###################### -->
<!-- ### Gripper Mimic #### -->
<!-- ###################### -->

  <link name="gripper_left_front_link">
    <inertial>
      <origin xyz="0 0 0" rpy="0 0 0" />
      <mass value="1"/>
      <inertia
        ixx="1.0" ixy="0.0" ixz="0.0"
        iyy="1.0" iyz="0.0"
        izz="1.0"/>
    </inertial>

    <visual>
      <origin xyz="0 0 0" rpy="0 0 0" />
      <geometry>
        <mesh filename="package://boris_description/meshes/gripper_left_front_link.STL" />
      </geometry>
      <material name="white"/>
    </visual>

    <collision>
      <origin xyz="0 0 0" rpy="0 0 0" />
      <geometry>
        <mesh filename="package://boris_description/meshes/gripper_left_front_link.STL" />
      </geometry>
    </collision>
  </link>

  <joint name="gripper_left_front_joint" type="revolute">
    <origin xyz="0.029999924913916 6.71204842689066E-05 0.000250000000000028" rpy="0 0 0" />
    <parent link="gripper_left_link" />
    <child  link="gripper_left_front_link" />
    <axis xyz="0 0 1" />
    <limit lower="-1.00" upper="0.00" effort="30.0" velocity="0.7" />
    <dynamics damping="1.0" />
    <mimic joint="gripper_right_joint" multiplier="1" offset="0" />
  </joint>

<!-- ###################### -->
<!-- ### Gripper Mimic #### -->
<!-- ###################### -->

  <link name="gripper_right_connection_link">
    <inertial>
      <origin xyz="0 0 0" rpy="0 0 0" />
      <mass value="1"/>
      <inertia
        ixx="1.0" ixy="0.0" ixz="0.0"
        iyy="1.0" iyz="0.0"
        izz="1.0"/>
    </inertial>

    <visual>
      <origin xyz="0 0 0" rpy="0 0 0" />
      <geometry>
        <mesh filename="package://boris_description/meshes/gripper_right_connection_link.STL" />
      </geometry>
      <material name="white"/>
    </visual>

    <collision>
      <origin xyz="0 0 0" rpy="0 0 0" />
      <geometry>
        <mesh filename="package://boris_description/meshes/gripper_right_connection_link.STL" />
      </geometry>
    </collision>
  </link>

  <joint name="gripper_right_connection_joint" type="revolute">
    <origin xyz="0.0664999999999999 -0.00656712048426952 0.00600000000000001"
            rpy="0 0 0" />
    <parent link="hand_link" />
    <child  link="gripper_right_connection_link" />
    <axis xyz="0 0 1" />
    <limit lower="-1.00" upper="0.00" effort="30.0" velocity="0.7" />
    <dynamics damping="1.0" />
    <mimic joint="gripper_right_joint" multiplier="1" offset="0" />
  </joint>

<!-- ###################### -->
<!-- ### Gripper Mimic #### -->
<!-- ###################### -->

  <link name="gripper_left_connection_link">
    <inertial>
      <origin xyz="0 0 0" rpy="0 0 0" />
      <mass value="1"/>
      <inertia
        ixx="1.0" ixy="0.0" ixz="0.0"
        iyy="1.0" iyz="0.0"
        izz="1.0"/>
    </inertial>

    <visual>
      <origin xyz="0 0 0" rpy="0 0 0" />
      <geometry>
        <mesh filename="package://boris_description/meshes/gripper_left_connection_link.STL" />
      </geometry>
      <material name="white"/>
    </visual>

    <collision>
      <origin xyz="0 0 0" rpy="0 0 0" />
      <geometry>
        <mesh filename="package://boris_description/meshes/gripper_left_connection_link.STL" />
      </geometry>
    </collision>
  </link>

  <joint name="gripper_left_connection_joint" type="revolute">
    <origin xyz="0.0665 0.00643287951573048 0.00600000000000001"
            rpy="0 0 0" />
    <parent link="hand_link" />
    <child  link="gripper_left_connection_link" />
    <axis xyz="0 0 -1" />
    <limit lower="-1.00" upper="0.00" effort="30.0" velocity="0.7" />
    <dynamics damping="1.0" />
    <mimic joint="gripper_right_joint" multiplier="1" offset="0" />
  </joint>

<!-- ###################### -->
<!-- ###   Materials   #### -->
<!-- ###################### -->

  <material name="white">
    <color rgba="1 1 1 1"/>
  </material>

<!-- ###################### -->
<!-- ###     Gazebo    #### -->
<!-- ###################### -->

  <gazebo>
    <plugin name="gazebo_ros_control" filename="libgazebo_ros_control.so">
      <robotNamespace>/boris_control</robotNamespace>
    </plugin>
  </gazebo>

<!-- ###################### -->
<!-- ### Transmissions #### -->
<!-- ###################### -->

  <transmission name="transmission1">
    <type>transmission_interface/SimpleTransmission</type>
    <joint name="base_rotation_joint">
      <hardwareInterface>hardware_interface/PositionJointInterface</hardwareInterface>
    </joint>
    <actuator name="motor1">
      <hardwareInterface>hardware_interface/PositionJointInterface</hardwareInterface>
      <mechanicalReduction>1</mechanicalReduction>
    </actuator>
  </transmission>

  <transmission name="transmission2">
    <type>transmission_interface/SimpleTransmission</type>
    <joint name="upper_arm_joint">
      <hardwareInterface>hardware_interface/PositionJointInterface</hardwareInterface>
    </joint>
    <actuator name="motor2">
      <hardwareInterface>hardware_interface/PositionJointInterface</hardwareInterface>
      <mechanicalReduction>1</mechanicalReduction>
    </actuator>
  </transmission>

  <transmission name="transmission3">
    <type>transmission_interface/SimpleTransmission</type>
    <joint name="lower_arm_joint">
      <hardwareInterface>hardware_interface/PositionJointInterface</hardwareInterface>
    </joint>
    <actuator name="motor3">
      <hardwareInterface>hardware_interface/PositionJointInterface</hardwareInterface>
      <mechanicalReduction>1</mechanicalReduction>
    </actuator>
  </transmission>

  <transmission name="transmission4">
    <type>transmission_interface/SimpleTransmission</type>
    <joint name="wrist_joint">
      <hardwareInterface>hardware_interface/PositionJointInterface</hardwareInterface>
    </joint>
    <actuator name="motor4">
      <hardwareInterface>hardware_interface/PositionJointInterface</hardwareInterface>
      <mechanicalReduction>1</mechanicalReduction>
    </actuator>
  </transmission>

  <transmission name="transmission5">
    <type>transmission_interface/SimpleTransmission</type>
    <joint name="hand_joint">
      <hardwareInterface>hardware_interface/PositionJointInterface</hardwareInterface>
    </joint>
    <actuator name="motor5">
      <hardwareInterface>hardware_interface/PositionJointInterface</hardwareInterface>
      <mechanicalReduction>1</mechanicalReduction>
    </actuator>
  </transmission>
  
<!-- ###################### -->
<!-- ####### Camera ####### -->
<!-- ###################### -->

  <link name="camera_link">
    <visual>
      <origin xyz="0 0 0" rpy="0 0 0"/>
      <geometry>
    <box size="0.01 0.01 0.01"/>
      </geometry>
      <material name="red"/>
    </visual>

    <inertial>
      <mass value="1e-5" />
      <origin xyz="0 0 0" rpy="0 0 0"/>
      <inertia ixx="1e-6" ixy="0" ixz="0"
               iyy="1e-6" iyz="0"
               izz="1e-6" />
    </inertial>
  </link>

  <joint name="camera_joint" type="fixed">
    <origin xyz="0 0 0.325"
            rpy="0 0.5 -1.57"/>
    <parent link="base_rotation_link"/>
    <child link="camera_link"/>
  </joint>

<!-- ###################### -->
<!-- #### Camera Frame #### -->
<!-- ###################### -->

  <link name="camera_rgb_optical_frame"/>

  <joint name="camera_rgb_optical_joint" type="fixed">
      <origin xyz="0 0 0"
              rpy="-1.57 0 -1.57" />
      <parent link="camera_link" />
      <child link="camera_rgb_optical_frame" />
  </joint>

<!-- ###################### -->
<!-- ###  Camera Plugin ### -->
<!-- ###################### -->

  <gazebo reference="camera_link">  
    <sensor type="depth"
            name="camera">
      <always_on>true</always_on>
      <update_rate>3.0</update_rate>
      <camera>
        <horizontal_fov>1.047197551</horizontal_fov>
        <image>
          <format>B8G8R8</format>
          <width>640</width>
          <height>480</height>
        </image>
        <clip>
          <near>0.2</near>
          <far>4.5</far>
        </clip>
      </camera>

      <plugin name="kinect_camera_controller" 
              filename="libgazebo_ros_openni_kinect.so">
        <cameraName>camera</cameraName>
        <alwaysOn>true</alwaysOn>
        <updateRate>10</updateRate>
        <imageTopicName>rgb/image_raw</imageTopicName>
        <depthImageTopicName>depth/image_raw</depthImageTopicName>
        <pointCloudTopicName>depth/points</pointCloudTopicName>
        <cameraInfoTopicName>rgb/camera_info</cameraInfoTopicName>
        <depthImageCameraInfoTopicName>depth/camera_info</depthImageCameraInfoTopicName>
        <frameName>camera_rgb_optical_frame</frameName>
        <baseline>0.1</baseline>
        <distortion_k1>0.0</distortion_k1>
        <distortion_k2>0.0</distortion_k2>
        <distortion_k3>0.0</distortion_k3>
        <distortion_t1>0.0</distortion_t1>
        <distortion_t2>0.0</distortion_t2>
        <pointCloudCutoff>0.4</pointCloudCutoff>
      </plugin>
    </sensor>
  </gazebo>


</robot>