<?xml version="1.0"?>

<robot name="boris_ros">


<!-- ++++++++++++++++++++++++++++++++++++++++++++++++++++++++++ -->
  <link name="base_link" />
      
  
<!-- ++++++++++++++++++++++++++++++++++++++++++++++++++++++++++ -->
  <link name="dummy_link">

    <inertial>
      <origin xyz="0 0 0" rpy="0 0 0" />
      <mass value="1"/>
      <inertia
        ixx="1.0" ixy="0.0" ixz="0.0"
        iyy="1.0" iyz="0.0"
        izz="1.0"/>
    </inertial>
    
    <visual>
      <origin xyz="0 0 0" py="0 0 0" />
      <geometry>
        <mesh filename="package://boris_ros/meshes/base_link.STL" />
      </geometry>
      <material name="red"/>
    </visual>
    
    <collision>
      <origin xyz="0 0 0" py="0 0 0" />
      <geometry>
        <mesh filename="package://boris_ros/meshes/base_link.STL" />
      </geometry>
    </collision>
    
  </link>
  
  
<!-- ++++++++++++++++++++++++++++++++++++++++++++++++++++++++++ -->
<!-- 58 - 138 - 219-->
  <joint name="dummy_joint" type="fixed">

    <origin xyz="0 0 0"
            rpy="0 0 0" />
    <parent link="base_link" />
    <child  link="dummy_link" />

  </joint>
  
  
<!-- ++++++++++++++++++++++++++++++++++++++++++++++++++++++++++ -->
  <link name="base_rotation_link">

    <inertial>
      <origin xyz="0 0 0" rpy="0 0 0" />
      <mass value="1"/>
      <inertia
        ixx="1.0" ixy="0.0" ixz="0.0"
        iyy="1.0" iyz="0.0"
        izz="1.0"/>
    </inertial>

    <visual>
      <origin xyz="0 0 0" py="0 0 0" />
      <geometry>
        <mesh filename="package://boris_ros/meshes/base_rotation_link.STL" />
      </geometry>
      <material name="red"/>
    </visual>

    <collision>
      <origin xyz="0 0 0" py="0 0 0" />
      <geometry>
        <mesh filename="package://boris_ros/meshes/base_rotation_link.STL" />
      </geometry>
    </collision>

  </link>


<!-- ++++++++++++++++++++++++++++++++++++++++++++++++++++++++++ -->
<!-- 58 - 138 - 219-->
  <joint name="base_rotation_joint" type="revolute">

    <origin xyz="0 0 0"
            rpy="0 0 0" />
    <parent link="dummy_link" />
    <child  link="base_rotation_link" />
    <axis xyz="0 0 1" />
    <limit lower="-1.40" upper="1.40" effort="30.0" velocity="0.7" />
    <dynamics damping="1.0" />

  </joint>


<!-- ++++++++++++++++++++++++++++++++++++++++++++++++++++++++++ -->
  <link name="upper_arm_link">

    <inertial>
      <origin xyz="0 0 0" rpy="0 0 0" />
      <mass value="1"/>
      <inertia
        ixx="1.0" ixy="0.0" ixz="0.0"
        iyy="1.0" iyz="0.0"
        izz="1.0"/>
    </inertial>

    <visual>
      <origin xyz="0 0 0" py="0 0 0" />
      <geometry>
        <mesh filename="package://boris_ros/meshes/upper_arm_link.STL" />
      </geometry>
      <material name="red"/>
    </visual>

    <collision>
      <origin xyz="0 0 0" py="0 0 0" />
      <geometry>
        <mesh filename="package://boris_ros/meshes/upper_arm_link.STL" />
      </geometry>
    </collision>
    
  </link>


<!-- ++++++++++++++++++++++++++++++++++++++++++++++++++++++++++ -->
<!-- 85 - 195 - 195 -->
  <joint name="upper_arm_joint" type="revolute">
  
    <origin xyz="0.00140595251037146 0.0289658988733059 0.071"
            rpy="-3.14159265358979 0 3.09309252060145" />
    <parent link="base_rotation_link" />
    <child  link="upper_arm_link" />
    <axis xyz="1 0 0" />
    <limit lower="-1.92" upper="-0.15" effort="30.0" velocity="0.7" />
    <dynamics damping="1.0" />

  </joint>


<!-- ++++++++++++++++++++++++++++++++++++++++++++++++++++++++++ -->
  <link name="elbow_link">

    <inertial>
      <origin xyz="0 0 0" rpy="0 0 0" />
      <mass value="1"/>
      <inertia
        ixx="1.0" ixy="0.0" ixz="0.0"
        iyy="1.0" iyz="0.0"
        izz="1.0"/>
    </inertial>

    <visual>
      <origin xyz="0 0 0" py="0 0 0" />
      <geometry>
        <mesh filename="package://boris_ros/meshes/elbow_link.STL" />
      </geometry>
      <material name="red"/>
    </visual>

    <collision>
      <origin xyz="0 0 0" py="0 0 0" />
      <geometry>
        <mesh filename="package://boris_ros/meshes/elbow_link.STL" />
      </geometry>
    </collision>

  </link>


<!-- ++++++++++++++++++++++++++++++++++++++++++++++++++++++++++ -->
  <joint name="elbow_joint" type="revolute">
  
    <origin xyz="0 0.104918520055473 -0.133761370168556"
            rpy="0 0 0" />
    <parent link="upper_arm_link" />
    <child  link="elbow_link" />
    <axis xyz="-1 0 0" />
    <limit lower="-1.92" upper="-0.15" effort="30.0" velocity="0.7" />
    <dynamics damping="1.0" />

    <!--mimic joint="upper_arm_joint" multiplier="1" offset="0" /-->

  </joint>
         
            
<!-- ++++++++++++++++++++++++++++++++++++++++++++++++++++++++++ -->
  <link name="lower_arm_link">

    <inertial>
      <origin xyz="0 0 0" rpy="0 0 0" />
      <mass value="1"/>
      <inertia
        ixx="1.0" ixy="0.0" ixz="0.0"
        iyy="1.0" iyz="0.0"
        izz="1.0"/>
    </inertial>

    <visual>
      <origin xyz="0 0 0" py="0 0 0" />
      <geometry>
        <mesh filename="package://boris_ros/meshes/lower_arm_link.STL" />
      </geometry>
      <material name="red"/>
    </visual>

    <collision>
      <origin xyz="0 0 0" py="0 0 0" />
      <geometry>
        <mesh filename="package://boris_ros/meshes/lower_arm_link.STL" />
      </geometry>
    </collision>

  </link>


<!-- ++++++++++++++++++++++++++++++++++++++++++++++++++++++++++ -->
<!-- 170 - 247 - 275 -->
  <joint name="lower_arm_joint" type="revolute">
  
    <origin xyz="0 -0.063999934489265 0.030000051384737"
            rpy="0 0 0" />
    <parent link="elbow_link" />
    <child  link="lower_arm_link" />
    <axis xyz="-1 0 0" />
    <limit lower="-1.34" upper="0.49" effort="30.0" velocity="0.7" />
    <dynamics damping="1.0" />
    
  </joint>


<!-- ++++++++++++++++++++++++++++++++++++++++++++++++++++++++++ -->
  <link name="wrist_link">

    <inertial>
      <origin xyz="0 0 0" rpy="0 0 0" />
      <mass value="1"/>
      <inertia
        ixx="1.0" ixy="0.0" ixz="0.0"
        iyy="1.0" iyz="0.0"
        izz="1.0"/>
    </inertial>

    <visual>
      <origin xyz="0 0 0" py="0 0 0" />
      <geometry>
        <mesh filename="package://boris_ros/meshes/wrist_link.STL" />
      </geometry>
      <material name="red"/>
    </visual>

    <collision>
      <origin xyz="0 0 0" py="0 0 0" />
      <geometry>
        <mesh filename="package://boris_ros/meshes/wrist_link.STL" />
      </geometry>
    </collision>

  </link>


<!-- ++++++++++++++++++++++++++++++++++++++++++++++++++++++++++ -->
  <joint name="wrist_joint" type="revolute">
  
    <origin xyz="0 -0.134699619920931 0.103711197048133"
            rpy="0 0 0" />
    <parent link="lower_arm_link" />
    <child  link="wrist_link" />
    <axis xyz="1 0 0" />
    <limit lower="-1.34" upper="0.49" effort="30.0" velocity="0.7" />
    <dynamics damping="1.0" />

    <!--mimic joint="lower_arm_joint" multiplier="1" offset="0" /-->

  </joint>


<!-- ++++++++++++++++++++++++++++++++++++++++++++++++++++++++++ -->
  <link name="hand_link">

    <inertial>
      <origin xyz="0 0 0" rpy="0 0 0" />
      <mass value="1"/>
      <inertia
        ixx="1.0" ixy="0.0" ixz="0.0"
        iyy="1.0" iyz="0.0"
        izz="1.0"/>
    </inertial>

    <visual>
      <origin xyz="0 0 0" py="0 0 0" />
      <geometry>
        <mesh filename="package://boris_ros/meshes/hand_link.STL" />
      </geometry>
      <material name="red"/>
    </visual>

    <collision>
      <origin xyz="0 0 0" py="0 0 0" />
      <geometry>
        <mesh filename="package://boris_ros/meshes/hand_link.STL" />
      </geometry>
    </collision>

  </link>
  
  
<!-- ++++++++++++++++++++++++++++++++++++++++++++++++++++++++++ -->
  <joint name="hand_joint" type="revolute">
  
    <origin xyz="0 -0.0615035978826819 -0.0219899396880796"
            rpy="0.000163577522470927 1.57 3.14159265229103" />
    <parent link="wrist_link" />
    <child  link="hand_link" />
    <axis xyz="0 1 0" />
    <limit lower="-3.14" upper="3.14" effort="30.0" velocity="0.7" />
    <dynamics damping="1.0" />
    
  </joint>


<!-- ++++++++++++++++++++++++++++++++++++++++++++++++++++++++++ -->
  <link name="finger_link">

    <inertial>
      <origin xyz="0 0 0" rpy="0 0 0" />
      <mass value="1"/>
      <inertia
        ixx="1.0" ixy="0.0" ixz="0.0"
        iyy="1.0" iyz="0.0"
        izz="1.0"/>
    </inertial>

    <visual>
      <origin xyz="0 0 0" py="0 0 0" />
      <geometry>
        <mesh filename="package://boris_ros/meshes/finger_link.STL" />
      </geometry>
      <material name="red"/>
    </visual>

    <collision>
      <origin xyz="0 0 0" py="0 0 0" />
      <geometry>
        <mesh filename="package://boris_ros/meshes/finger_link.STL" />
      </geometry>
    </collision>

  </link>


<!-- ++++++++++++++++++++++++++++++++++++++++++++++++++++++++++ -->
  <joint name="finger_joint" type="revolute">
  
    <origin xyz="-0.0083508045333599 0.0339422712461613 -0.00927912860378688"
            rpy="1.57 -1.51887678541298 0" />
    <parent link="hand_link" />
    <child  link="finger_link" />
    <axis xyz="-1 0 0" />
    <limit lower="-1.57" upper="1.57" effort="30.0" velocity="0.7" />
    <dynamics damping="1.0" />
    
  </joint>


<!-- ++++++++++++++++++++++++++++++++++++++++++++++++++++++++++ -->
  <link name="gripper_left_link">
  
    <inertial>
      <origin xyz="0 0 0" rpy="0 0 0" />
      <mass value="1"/>
      <inertia
        ixx="1.0" ixy="0.0" ixz="0.0"
        iyy="1.0" iyz="0.0"
        izz="1.0"/>
    </inertial>
    
    <visual>
      <origin xyz="0 0 0" rpy="0 0 0" />
      <geometry>
        <mesh filename="package://boris_ros/meshes/gripper_left_link.STL" />
      </geometry>
      <material name="red"/>
    </visual>
    
    <collision>
      <origin xyz="0 0 0" rpy="0 0 0" />
      <geometry>
        <mesh filename="package://boris_ros/meshes/gripper_left_link.STL" />
      </geometry>
    </collision>
    
  </link>
  
  
<!-- ++++++++++++++++++++++++++++++++++++++++++++++++++++++++++ -->
  <joint name="gripper_left_joint" type="revolute">
  
    <origin xyz="0.0302 0.00480047324341529 -0.0534125028119752"
            rpy="-1.59151598544766 -0.113765805320385 -3.1392402140541" />
    <parent link="finger_link" />
    <child  link="gripper_left_link" />
    <axis   xyz="0 0 -1" />
    <limit lower="-1.00" upper="0.00" effort="30.0" velocity="0.7" />
    <dynamics damping="1.0" />
    
  </joint>
  
  
<!-- ++++++++++++++++++++++++++++++++++++++++++++++++++++++++++ -->
  <link name="gripper_left_front_link">
    <inertial>
      <origin xyz="0 0 0" rpy="0 0 0" />
      <mass value="1"/>
      <inertia
        ixx="1.0" ixy="0.0" ixz="0.0"
        iyy="1.0" iyz="0.0"
        izz="1.0"/>
    </inertial>
    
    <visual>
      <origin xyz="0 0 0" rpy="0 0 0" />
      <geometry>
        <mesh filename="package://boris_ros/meshes/gripper_left_front_link.STL" />
      </geometry>
      <material name="red"/>
    </visual>
    
    <collision>
      <origin xyz="0 0 0" rpy="0 0 0" />
      <geometry>
        <mesh filename="package://boris_ros/meshes/gripper_left_front_link.STL" />
      </geometry>
    </collision>
    
  </link>
  
  
<!-- ++++++++++++++++++++++++++++++++++++++++++++++++++++++++++ --> 
  <joint name="gripper_left_front_joint" type="revolute">
  
    <origin xyz="-0.00347301637463621 0.0297982911802257 0.0069500000000001"
            rpy="-3.14158470285278 -6.76225140133075E-05 3.13832942623202" />
    <parent link="gripper_left_link" />
    <child  link="gripper_left_front_link" />
    <axis   xyz="0 0 1" />
    <limit lower="0.00" upper="1.00" effort="30.0" velocity="0.7" />
    <dynamics damping="1.0" />
    
    <mimic joint="gripper_left_joint" multiplier="-1" offset="0" />
        
  </joint>
  
  
<!-- ++++++++++++++++++++++++++++++++++++++++++++++++++++++++++ -->
  <link name="gripper_right_link">
  
    <inertial>
      <origin xyz="0 0 0" rpy="0 0 0" />
      <mass value="1"/>
      <inertia
        ixx="1.0" ixy="0.0" ixz="0.0"
        iyy="1.0" iyz="0.0"
        izz="1.0"/>
    </inertial>
    
    <visual>
      <origin xyz="0 0 0" rpy="0 0 0" />
      <geometry>
        <mesh filename="package://boris_ros/meshes/gripper_right_link.STL" />
      </geometry>
      <material name="red"/>
    </visual>
    
    <collision>
      <origin xyz="0 0 0" rpy="0 0 0" />
      <geometry>
        <mesh filename="package://boris_ros/meshes/gripper_right_link.STL" />
      </geometry>
    </collision>
    
  </link>
  
  
<!-- ++++++++++++++++++++++++++++++++++++++++++++++++++++++++++ --> 
  <joint name="gripper_right_joint" type="revolute">
  
    <origin xyz="-0.00879999999999999 0.00480047324341523 -0.0534125028119751"
            rpy="-1.59151598544766 -0.113765805320409 -3.1392402140541" />
    <parent link="finger_link" />
    <child  link="gripper_right_link" />
    <axis   xyz="0 0 -1" />
    <limit lower="0.00" upper="1.00" effort="30.0" velocity="0.7" />
    <dynamics damping="1.0" />
    
    <mimic joint="gripper_left_joint" multiplier="-1" offset="0" />
        
  </joint>


<!-- ++++++++++++++++++++++++++++++++++++++++++++++++++++++++++ -->
  <link name="gripper_right_front_link">
  
    <inertial>
      <origin xyz="0 0 0" rpy="0 0 0" />
      <mass value="1"/>
      <inertia
        ixx="1.0" ixy="0.0" ixz="0.0"
        iyy="1.0" iyz="0.0"
        izz="1.0"/>
    </inertial>
    
    <visual>
      <origin xyz="0 0 0" rpy="0 0 0" />
      <geometry>
        <mesh filename="package://boris_ros/meshes/gripper_right_front_link.STL" />
      </geometry>
      <material name="red"/>
    </visual>
    
    <collision>
      <origin xyz="0 0 0" rpy="0 0 0" />
      <geometry>
        <mesh filename="package://boris_ros/meshes/gripper_right_front_link.STL" />
      </geometry>
    </collision>
    
  </link>
  
  
<!-- ++++++++++++++++++++++++++++++++++++++++++++++++++++++++++ --> 
  <joint name="gripper_right_front_joint" type="revolute">
  
    <origin xyz="-0.00347301637463691 0.0297982911802257 0.00695000000000001"
            rpy="-6.79968002564964E-05 -3.52899069022653E-06 -1.50887443585772" />
    <parent link="gripper_right_link" />
    <child  link="gripper_right_front_link" />
    <axis   xyz="0 0 -1" />
    <limit lower="-1.00" upper="0.00" effort="30.0" velocity="0.7" />
    <dynamics damping="1.0" />
    
    <mimic joint="gripper_left_joint" multiplier="1" offset="0" />
        
  </joint>


<!-- ++++++++++++++++++++++++++++++++++++++++++++++++++++++++++ -->
  <link name="gripper_left_connection_link">
  
    <inertial>
      <origin xyz="0 0 0" rpy="0 0 0" />
      <mass value="1"/>
      <inertia
        ixx="1.0" ixy="0.0" ixz="0.0"
        iyy="1.0" iyz="0.0"
        izz="1.0"/>
    </inertial>
    
    <visual>
      <origin xyz="0 0 0" rpy="0 0 0" />
      <geometry>
        <mesh filename="package://boris_ros/meshes/gripper_left_connection_link.STL" />
      </geometry>
      <material name="red"/>
    </visual>
    
    <collision>
      <origin xyz="0 0 0" rpy="0 0 0" />
      <geometry>
        <mesh filename="package://boris_ros/meshes/gripper_left_connection_link.STL" />
      </geometry>
    </collision>
    
  </link>
  
  
<!-- ++++++++++++++++++++++++++++++++++++++++++++++++++++++++++ --> 
  <joint name="gripper_left_connection_joint" type="revolute">
  
    <origin xyz="0.0172 -0.00462987633392004 -0.0666094155891838"
            rpy="1.94880773705823 -1.5149945428384 -0.377545489148437" />
    <parent link="finger_link" />
    <child  link="gripper_left_connection_link" />
    <axis   xyz="0 0 -1" />
    <limit lower="-1.00" upper="0.00" effort="30.0" velocity="0.7" />
    <dynamics damping="1.0" />
    
    <mimic joint="gripper_left_joint" multiplier="1" offset="0" />
       
  </joint>


<!-- ++++++++++++++++++++++++++++++++++++++++++++++++++++++++++ -->
  <link name="gripper_right_connection_link">
  
    <inertial>
      <origin xyz="0 0 0" rpy="0 0 0" />
      <mass value="1"/>
      <inertia
        ixx="1.0" ixy="0.0" ixz="0.0"
        iyy="1.0" iyz="0.0"
        izz="1.0"/>
    </inertial>
    
    <visual>
      <origin xyz="0 0 0" rpy="0 0 0" />
      <geometry>
        <mesh filename="package://boris_ros/meshes/gripper_right_connection_link.STL" />
      </geometry>
      <material name="red"/>
    </visual>
    
    <collision>
      <origin xyz="0 0 0" rpy="0 0 0" />
      <geometry>
        <mesh filename="package://boris_ros/meshes/gripper_right_connection_link.STL" />
      </geometry>
    </collision>
    
  </link>
  
  
<!-- ++++++++++++++++++++++++++++++++++++++++++++++++++++++++++ --> 
  <joint name="gripper_right_connection_joint" type="revolute">
  
    <origin xyz="0.0042 -0.00462987633392001 -0.0666094155891838"
            rpy="-1.59152382585076 -0.117029733257198 -3.1392402140541" />
    <parent link="finger_link" />
    <child  link="gripper_right_connection_link" />
    <axis   xyz="0 0 -1" />
    <limit lower="0.00" upper="1.00" effort="30.0" velocity="0.7" />
    <dynamics damping="1.0" />
    
    <mimic joint="gripper_left_joint" multiplier="-1" offset="0" />
        
  </joint>


<!-- ++++++++++++++++++++++++++++++++++++++++++++++++++++++++++ -->
  <link name="lower_support_link">
  
    <inertial>
      <origin xyz="0 0 0" rpy="0 0 0" />
      <mass value="1"/>
      <inertia
        ixx="1.0" ixy="0.0" ixz="0.0"
        iyy="1.0" iyz="0.0"
        izz="1.0"/>
    </inertial>
    
    <visual>
      <origin xyz="0 0 0" rpy="0 0 0" />
      <geometry>
        <mesh filename="package://boris_ros/meshes/lower_support_link.STL" />
      </geometry>
      <material name="red"/>
    </visual>
    
    <collision>
      <origin xyz="0 0 0" rpy="0 0 0" />
      <geometry>
        <mesh filename="package://boris_ros/meshes/lower_support_link.STL" />
      </geometry>
    </collision>
    
  </link>
  
  
<!-- ++++++++++++++++++++++++++++++++++++++++++++++++++++++++++ --> 
  <joint name="lower_support_joint" type="revolute">
  
    <origin xyz="0 -0.0939980623488527 -0.0339790104160389"
            rpy="0 0 0" />
    <parent link="elbow_link" />
    <child  link="lower_support_link" />
    <axis   xyz="-1 0 0" />
    <limit lower="-1.34" upper="0.49" effort="30.0" velocity="0.7" />
    <dynamics damping="1.0" />
    
    <!--mimic joint="lower_arm_joint" multiplier="1" offset="0" /-->
        
  </joint>


<!-- ++++++++++++++++++++++++++++++++++++++++++++++++++++++++++ -->
  <link name="upper_support_link">
  
    <inertial>
      <origin xyz="0 0 0" rpy="0 0 0" />
      <mass value="1"/>
      <inertia
        ixx="1.0" ixy="0.0" ixz="0.0"
        iyy="1.0" iyz="0.0"
        izz="1.0"/>
    </inertial>
    
    <visual>
      <origin xyz="0 0 0" rpy="0 0 0" />
      <geometry>
        <mesh filename="package://boris_ros/meshes/upper_support_link.STL" />
      </geometry>
      <material name="red"/>
    </visual>
    
    <collision>
      <origin xyz="0 0 0" rpy="0 0 0" />
      <geometry>
        <mesh filename="package://boris_ros/meshes/upper_support_link.STL" />
      </geometry>
    </collision>
    
  </link>
  
  
<!-- ++++++++++++++++++++++++++++++++++++++++++++++++++++++++++ --> 
  <joint name="upper_support_joint" type="revolute">
  
    <origin xyz="-0.002650339306241 -0.0349125622934152 0.041"
            rpy="0 0 -0.0485001329883457" />
    <parent link="base_rotation_link" />
    <child  link="upper_support_link" />
    <axis   xyz="-1 0 0" />
    <limit lower="-1.92" upper="-0.15" effort="30.0" velocity="0.7" />
    <dynamics damping="1.0" />
    
    <!--mimic joint="upper_arm_joint" multiplier="1" offset="0" /-->
          
  </joint>


<!-- ++++++++++++++++++++++++++++++++++++++++++++++++++++++++++ --> 
  <material name="red">
    <color rgba="1 0 0 1"/>
  </material>

<!-- ++++++++++++++++++++++++++++++++++++++++++++++++++++++++++ --> 
  <gazebo>
    <plugin name="gazebo_ros_control" filename="libgazebo_ros_control.so">
      <robotNamespace>/boris_control</robotNamespace>
    </plugin>
  </gazebo>


<!-- ++++++++++++++++++++++++++++++++++++++++++++++++++++++++++ --> 
  <transmission name="transmission1">
    <type>transmission_interface/SimpleTransmission</type>
    <joint name="base_rotation_joint">
      <hardwareInterface>hardware_interface/PositionJointInterface</hardwareInterface>
    </joint>
    <actuator name="motor1">
      <hardwareInterface>hardware_interface/PositionJointInterface</hardwareInterface>
      <mechanicalReduction>1</mechanicalReduction>
    </actuator>
  </transmission>

  <transmission name="transmission2">
    <type>transmission_interface/SimpleTransmission</type>
    <joint name="upper_arm_joint">
      <hardwareInterface>hardware_interface/PositionJointInterface</hardwareInterface>
    </joint>
    <actuator name="motor2">
      <hardwareInterface>hardware_interface/PositionJointInterface</hardwareInterface>
      <mechanicalReduction>1</mechanicalReduction>
    </actuator>
  </transmission>

  <transmission name="transmission3">
    <type>transmission_interface/SimpleTransmission</type>
    <joint name="lower_arm_joint">
      <hardwareInterface>hardware_interface/PositionJointInterface</hardwareInterface>
    </joint>
    <actuator name="motor3">
      <hardwareInterface>hardware_interface/PositionJointInterface</hardwareInterface>
      <mechanicalReduction>1</mechanicalReduction>
    </actuator>
  </transmission>

  <transmission name="transmission4">
    <type>transmission_interface/SimpleTransmission</type>
    <joint name="hand_joint">
      <hardwareInterface>hardware_interface/PositionJointInterface</hardwareInterface>
    </joint>
    <actuator name="motor4">
      <hardwareInterface>hardware_interface/PositionJointInterface</hardwareInterface>
      <mechanicalReduction>1</mechanicalReduction>
    </actuator>
  </transmission>

  <transmission name="transmission5">
    <type>transmission_interface/SimpleTransmission</type>
    <joint name="finger_joint">
      <hardwareInterface>hardware_interface/PositionJointInterface</hardwareInterface>
    </joint>
    <actuator name="motor5">
      <hardwareInterface>hardware_interface/PositionJointInterface</hardwareInterface>
      <mechanicalReduction>1</mechanicalReduction>
    </actuator>
  </transmission>

  <transmission name="transmission6">
    <type>transmission_interface/SimpleTransmission</type>
    <joint name="elbow_joint">
      <hardwareInterface>hardware_interface/PositionJointInterface</hardwareInterface>
    </joint>
    <actuator name="motor6">
      <hardwareInterface>hardware_interface/PositionJointInterface</hardwareInterface>
      <mechanicalReduction>1</mechanicalReduction>
    </actuator>
  </transmission>

  <transmission name="transmission7">
    <type>transmission_interface/SimpleTransmission</type>
    <joint name="wrist_joint">
      <hardwareInterface>hardware_interface/PositionJointInterface</hardwareInterface>
    </joint>
    <actuator name="motor7">
      <hardwareInterface>hardware_interface/PositionJointInterface</hardwareInterface>
      <mechanicalReduction>1</mechanicalReduction>
    </actuator>
  </transmission>
  
  
</robot>
